# 异常处理

## 什么是异常

异常就是：**程序发生了意想不到的情况，这种情况影响到了程序的正确运行。**

**错误对象只有在抛出错误的时才会变成异常**

```javascript
const err1 = new Error('aaa');
console.log(err1.name); // Error
console.log('这行代码会执行。Error 就是一个 错误对象，只要不被抛出，就不会产生错误');
```

我们使用 `throw` 把错误抛出去。

```javascript
throw TypeError('抛出一个类型错误'); // 省略了 new 关键字
```

**`throw` 可以抛出任何东西，不仅仅 Error 对象**

```javascript
throw 3;
throw '发生了错误';
throw () => false;
throw { name: 'name', description: 'description' };
throw Error('error');
```

当抛出异常之后，它就会在程序栈种冒泡，除非它在某个地方被捕获。

## 异常分类

按照异常时程序是否正在运行，我们讲错误分为：**编译时异常** 和 **运行时异常**。

- 编译时异常是指：源代码在编译成可执行代码之前产生的异常。
- 运行时异常是指：可执行代码被装载到内存中执行之后产生的异常。

## 异常类型和捕获错误的手段

| 处理手段 \ 异常类型            | 同步方法 | 异步方法 | 资源加载 | Promise | async/await |
| ------------------------------ | -------- | -------- | -------- | ------- | ----------- | --- |
| try/catch                      | ✅       |          |          |         | ✅          |
| window.onerror/element.onerror | ✅       | ✅       |          |         |             |     |
| error                          | ✅       | ✅       | ✅       |         |             |
| unhandledrejection             |          |          |          | ✅      | ✅          |

这里说的异步方法是指：`setTimeout`、`requestAnimationFrame`，不包括 Promise 和 async。

### try/catch

> 能捕获常规运行时错误，语法错误和异步错误不行能捕获当前调用栈的作用 try/catch 能捕获 `同步方法` + `async/await` 错误。

try/catch 不能捕获语法错误，因为在解析阶段、构建阶段就被捕获了。

更多的示例可以看 trycatch.js

### onerror 事件

当资源加载错误的时候，会触发元素的 onerror 事件。但是不会冒泡到 window

```javascript
img.onerror = (event) => {
  console.log('img.onerror', event);
};
```

```javascript
window.onerror = function (event, source) {
  console.log('window.onerror 收到了错误');

  // 返回 true 可以阻止浏览器打印错误
  return true;
};
```

### error 事件

error 事件可以捕获资源加载错误。img、script、css 加载错误，都能被捕获。

> 当一项资源（如图片或者脚本）加载失败，加载资源的元素会触发一个 Event 接口的 error 事件，这些 error 事件不会向上冒泡到 window，但能被捕获。 而 window.onerror 不能监测捕获

需要注意的是，这里要采用 **捕获** 的方式

```javascript
window.addEventListener(
  'error',
  (event) => {
    console.log('window.addEventListener', event);
  },
  true,
);
```

### unhandledrejection 事件

可以用来处理未处理的 Promise 错误和 async 错误需要注意的是：这里要采用 **捕获** 的方式。

```javascript
window.addEventListener('unhandledrejection', onRejected, true);
```

### Promise 错误

Promise 内部的错误，不会影响到 Promise 外部的代码。Promise onRejected 或者 Promise 中 throw 一个错误之后，不会影响到后面的代码执行，会在控制台报错。通俗的说法就是 “Promise 会吃掉错误”。

### `Script Error.`

出现这个错误，一般就是出现了跨域问题

如果当前页面和云端 JS 在不同域名，如果云端 JS 出现错误，window.onerror 会出现 Script Error。

这不是一个 JS 错误，有时也被称为跨域错误。 **当网站请求并执行一个托管在第三方域名下的脚本时，就可能遇到该错误** 出于安全考虑，浏览器会刻意隐藏其他域的 JS 文件抛出的具体错误信息，这样做可以有效避免敏感信息无意中被不受控制的第三方脚本捕获

#### 解法 1：开启 CORS (跨站资源共享)

**后端配置 Access-Control-Allow-Origin** + **前端 script 中加 crossorigin = anonymous**

```html
<!-- 意思就是告诉浏览器以匿名的方式获取目标脚本。 -->
<script src="http://another-domain.com/app.js" crossorigin="anonymous"></script>
```

#### 解法 2：try/catch

```html
<script src="http://another-domain.com/app.js"></script>

<script>
  window.onerror = function (message, url, line, column, error) {
    console.log(message, url, line, column, error);
  };
  try {
    foo(); // 调用 app.js 中定义的 foo 方法
  } catch (e) {
    throw e;
  }
</script>
```

crossorigin="anonymous" 的作用:

1. 安全。不用泄露用户的凭证信息
2. 错误处理。不加的话跨域脚本出现错误，只会显示 Script Error. 不会给出具体细节，加了之后，会给出具体细节
3. 不加的话，这个资源不可被脚本读取或修改。比如这个资源是一个图片，想要二次加工，就需要加上这个。

这种写法 等同于 crossorigin 。

## Error 实例对象

```javascript
const err = new Error('出错了');
err.message; // 出错了
err.name; // Error

// 也可以省略 `new`
const typeError = TypeError('类型错误');
typeError.name; // TypeError
```

实例对象的属性：

- **message**：错误提示信息
- **name**：错误类型名称
- **stack**：错误的堆栈

## 原生错误类型

**Error** 实例对象是最一般的错误类型，在它的基础上，JS 还定义了其他 **6** 种错误对象。也就是说，存在 **Error** 的 6 个派生对象

### TypeError

**类型错误。值不是预期类型时发生的错误**

```javascript
new 123
// Uncaught TypeError: number is not a func

➤ 1();
// Uncaught TypeError: 1 is not a function

➤ null.name;
// Uncaught TypeError: Cannot read property 'name' of null

```

### SyntaxError

**语法错误**

```javascript
// 变量名错误
var 1a;
// Uncaught SyntaxError: Invalid or unexpected token

// 缺少括号
console.log 'hello');
// Uncaught SyntaxError: Unexpected string
```

### ReferenceError

**引用错误** 引用一个未声明的变量时发生的错误。

```javascript
// 使用一个不存在的变量
unknownVariable;
// Uncaught ReferenceError: unknownVariable is not defined
```

### RangeError

**一个值超出有效范围时发生的错误** 主要有几种情况：

1. 数组长度为负数
2. `Number` 对象的方法参数超出范围，以及函数堆栈超过最大值。

```javascript
// 数组长度不得为负数
new Array(-1);
// Uncaught RangeError: Invalid array length
```

### URIError

**URI 相关函数的参数不正确时抛出的错误** 主要涉及以下 6 个函数：

1. `encodeURI()`
2. `decodeURI()`
3. `encodeURIComponent()`
4. `decodeURIComponent()`
5. `escape()`
6. `unescape()`

```javascript
decodeURI('%2');
// URIError: URI malformed
```

### EvalError

**`eval` 函数没有被正确执行时，会抛出 `EvalError` 错误**

## 自定义异常

如果是 ES5 可以使用 **`function` + `原型`** 的方式自定义一个异常，如果是 ES6 可以使用 **`Class` + `extends`** 来实现

```javascript
// ES6 方式
class CustomError extends Error {
  constructor(message, code) {
    super(message);
    this.code = code;
    this.name = 'CustomError';
  }
}

const e1 = new CustomError('自定义错误', 'custom');
```

```javascript
// ES5 方式
function UserError(message) {
  this.message = message || '默认信息';
  this.name = 'UserError';
}

UserError.prototype = Object.create(Error.prototype);
Object.defineProperty(UserError.prototype, 'contructor', {
  value: UserError,
  enumerable: false,
});
```
